#VRML_SIM R2019a utf8
WorldInfo {
}
Viewpoint {
  orientation -0.9072456303524448 -0.4184999420944084 -0.04199005445783232 0.2202900498761493
  position 0.46166929921765687 1.3176864948736848 3.517550244005735
}
TexturedBackground {
}
TexturedBackgroundLight {
}
Floor {
}
Solid {
  children [
    DEF BASE_C Group {
      children [
        DEF GROUPA Group {
          children [
            Transform {
              translation 0 0.45 0
              rotation 1 0 0 0.45
              children [
                Shape {
                  appearance DEF BLUE PBRAppearance {
                    baseColor 0.12549019607843137 0.2901960784313726 0.5294117647058824
                  }
                  geometry DEF BAR1 Cylinder {
                    height 1
                    radius 0.03
                  }
                }
              ]
            }
            Transform {
              translation 0 0.45 0.42
              rotation 1 0 0 -0.45
              children [
                Shape {
                  appearance USE BLUE
                  geometry USE BAR1
                }
              ]
            }
            Transform {
              translation 0 0.5 0.2
              rotation 1 0 0 1.57
              children [
                Shape {
                  appearance USE BLUE
                  geometry Cylinder {
                    height 0.4
                    radius 0.03
                  }
                }
              ]
            }
          ]
        }
        Transform {
          translation 1.0199999999999996 0 0
          children [
            USE GROUPA
          ]
        }
        Transform {
          translation 0.5002944823488886 0.8696017193294119 0.19000000000000003
          rotation 0 0 1 1.57
          children [
            Shape {
              appearance USE BLUE
              geometry USE BAR1
            }
            HingeJoint {
              jointParameters HingeJointParameters {
              }
              endPoint Solid {
                translation -0.05 0 0
                children [
                  Shape {
                    appearance PBRAppearance {
                      baseColor 0.8 0 0
                    }
                    geometry Box {
                      size 0.05 0.1 0.1
                    }
                  }
                ]
              }
            }
          ]
        }
      ]
    }
  ]
}
